Traceback (most recent call last):
  File "/usr/lib/python3.9/site-packages/urllib3/connection.py", line 159, in _new_conn
    conn = connection.create_connection(
  File "/usr/lib/python3.9/site-packages/urllib3/util/connection.py", line 84, in create_connection
    raise err
  File "/usr/lib/python3.9/site-packages/urllib3/util/connection.py", line 74, in create_connection
    sock.connect(sa)
ConnectionRefusedError: [Errno 111] Connection refused

During handling of the above exception, another exception occurred:

Traceback (most recent call last):
  File "/usr/lib/python3.9/site-packages/urllib3/connectionpool.py", line 670, in urlopen
    httplib_response = self._make_request(
  File "/usr/lib/python3.9/site-packages/urllib3/connectionpool.py", line 381, in _make_request
    self._validate_conn(conn)
  File "/usr/lib/python3.9/site-packages/urllib3/connectionpool.py", line 978, in _validate_conn
    conn.connect()
  File "/usr/lib/python3.9/site-packages/urllib3/connection.py", line 309, in connect
    conn = self._new_conn()
  File "/usr/lib/python3.9/site-packages/urllib3/connection.py", line 171, in _new_conn
    raise NewConnectionError(
urllib3.exceptions.NewConnectionError: <urllib3.connection.HTTPSConnection object at 0x7faa72670160>: Failed to establish a new connection: [Errno 111] Connection refused

During handling of the above exception, another exception occurred:

Traceback (most recent call last):
  File "/home/kevin/openshift/matrix_benchmark/exec/mlperf/run_ssd.py", line 603, in <module>
    sys.exit(main())
  File "/home/kevin/openshift/matrix_benchmark/exec/mlperf/run_ssd.py", line 580, in main
    apply_gpu_strategy(gpu_config.mig_strategy)
  File "/home/kevin/openshift/matrix_benchmark/exec/mlperf/run_ssd.py", line 493, in apply_gpu_strategy
    customv1.patch_cluster_custom_object("nvidia.com", "v1",
  File "/home/kevin/.local/lib/python3.9/site-packages/kubernetes/client/api/custom_objects_api.py", line 2290, in patch_cluster_custom_object
    return self.patch_cluster_custom_object_with_http_info(group, version, plural, name, body, **kwargs)  # noqa: E501
  File "/home/kevin/.local/lib/python3.9/site-packages/kubernetes/client/api/custom_objects_api.py", line 2413, in patch_cluster_custom_object_with_http_info
    return self.api_client.call_api(
  File "/home/kevin/.local/lib/python3.9/site-packages/kubernetes/client/api_client.py", line 348, in call_api
    return self.__call_api(resource_path, method,
  File "/home/kevin/.local/lib/python3.9/site-packages/kubernetes/client/api_client.py", line 180, in __call_api
    response_data = self.request(
  File "/home/kevin/.local/lib/python3.9/site-packages/kubernetes/client/api_client.py", line 407, in request
    return self.rest_client.PATCH(url,
  File "/home/kevin/.local/lib/python3.9/site-packages/kubernetes/client/rest.py", line 294, in PATCH
    return self.request("PATCH", url,
  File "/home/kevin/.local/lib/python3.9/site-packages/kubernetes/client/rest.py", line 167, in request
    r = self.pool_manager.request(
  File "/usr/lib/python3.9/site-packages/urllib3/request.py", line 79, in request
    return self.request_encode_body(
  File "/usr/lib/python3.9/site-packages/urllib3/request.py", line 171, in request_encode_body
    return self.urlopen(method, url, **extra_kw)
  File "/usr/lib/python3.9/site-packages/urllib3/poolmanager.py", line 336, in urlopen
    response = conn.urlopen(method, u.request_uri, **kw)
  File "/usr/lib/python3.9/site-packages/urllib3/connectionpool.py", line 754, in urlopen
    return self.urlopen(
  File "/usr/lib/python3.9/site-packages/urllib3/connectionpool.py", line 754, in urlopen
    return self.urlopen(
  File "/usr/lib/python3.9/site-packages/urllib3/connectionpool.py", line 754, in urlopen
    return self.urlopen(
  File "/usr/lib/python3.9/site-packages/urllib3/connectionpool.py", line 726, in urlopen
    retries = retries.increment(
  File "/usr/lib/python3.9/site-packages/urllib3/util/retry.py", line 439, in increment
    raise MaxRetryError(_pool, url, error or ResponseError(cause))
urllib3.exceptions.MaxRetryError: HTTPSConnectionPool(host='api.nvidia-test.nvidia-ocp.net', port=6443): Max retries exceeded with url: /apis/nvidia.com/v1/clusterpolicies/gpu-cluster-policy (Caused by NewConnectionError('<urllib3.connection.HTTPSConnection object at 0x7faa72670160>: Failed to establish a new connection: [Errno 111] Connection refused'))
